[INFO   ] Logger: Record log in /Users/m-takeuchi/research/kyoto-u/exp_data/ILIS/ILIS_program_t-i/ilislife/logs/kivy_16-07-21_1.txt
[INFO   ] Factory: 193 symbols loaded
[DEBUG  ] Cache: register <kv.image> with limit=None, timeout=60
[DEBUG  ] Cache: register <kv.atlas> with limit=None, timeout=None
[INFO   ] Image: Providers: img_tex, img_imageio, img_dds, img_gif, img_sdl2, img_pil (img_ffpyplayer ignored)
[DEBUG  ] Cache: register <kv.texture> with limit=1000, timeout=60
[DEBUG  ] Cache: register <kv.shader> with limit=1000, timeout=3600
[DEBUG  ] Cache: register <kv.lang> with limit=None, timeout=None
[INFO   ] Text: Provider: sdl2
[DEBUG  ] Cache: register <textinput.label> with limit=None, timeout=60.0
[DEBUG  ] Cache: register <textinput.width> with limit=None, timeout=60.0
[DEBUG  ] App: Loading kv <./ilislife.kv>
[INFO   ] OSC: using <multiprocessing> for socket
[INFO   ] Window: Provider: sdl2
[INFO   ] GL: OpenGL version <b'2.1 INTEL-10.14.66'>
[INFO   ] GL: OpenGL vendor <b'Intel Inc.'>
[INFO   ] GL: OpenGL renderer <b'Intel Iris OpenGL Engine'>
[INFO   ] GL: OpenGL parsed version: 2, 1
[INFO   ] GL: Shading version <b'1.20'>
[INFO   ] GL: Texture max size <16384>
[INFO   ] GL: Texture max units <16>
[DEBUG  ] Shader: Fragment compiled successfully
[DEBUG  ] Shader: Vertex compiled successfully
[DEBUG  ] ImageImageIO: Load </Users/m-takeuchi/.pyenv/versions/3.4.3/lib/python3.4/site-packages/kivy/data/glsl/default.png>
[INFO   ] Window: auto add sdl2 input provider
[INFO   ] Window: virtual keyboard not allowed, single mode, not docked
[DEBUG  ] Resource: add </Library/Fonts> in path list
[DEBUG  ] Resource: add </Library/Fonts/Microsoft> in path list
[DEBUG  ] Resource: add </System/Library/Fonts> in path list
[DEBUG  ] Resource: add </Users/m-takeuchi/Library/Fonts> in path list
[DEBUG  ] Resource: add </Users/m-takeuchi/.pyenv/versions/3.4.3/lib/python3.4/site-packages/kivy/data/fonts> in path list
[DEBUG  ] Base: Create provider from mouse
[INFO   ] Base: Start application main loop
[INFO   ] GL: NPOT texture support is available
[DEBUG  ] Atlas: Load </Users/m-takeuchi/.pyenv/versions/3.4.3/lib/python3.4/site-packages/kivy/data/../data/images/defaulttheme.atlas>
[DEBUG  ] Atlas: Need to load 1 images
[DEBUG  ] Atlas: Load </Users/m-takeuchi/.pyenv/versions/3.4.3/lib/python3.4/site-packages/kivy/data/../data/images/defaulttheme-0.png>
[DEBUG  ] ImageImageIO: Load </Users/m-takeuchi/.pyenv/versions/3.4.3/lib/python3.4/site-packages/kivy/data/../data/images/defaulttheme-0.png>
[INFO   ] Base: Leaving application in progress...
[WARNING] stderr: Traceback (most recent call last):
[WARNING] stderr:   File "/Users/m-takeuchi/.pyenv/versions/3.4.3/lib/python3.4/site-packages/serial/serialposix.py", line 244, in open
[WARNING] stderr:     self.fd = os.open(self.portstr, os.O_RDWR | os.O_NOCTTY | os.O_NONBLOCK)
[WARNING] stderr: FileNotFoundError: [Errno 2] No such file or directory: '/dev/tty.usbserial-PXWV0AMC'
[WARNING] stderr: 
[WARNING] stderr: During handling of the above exception, another exception occurred:
[WARNING] stderr: 
[WARNING] stderr: Traceback (most recent call last):
[WARNING] stderr:   File "main.py", line 553, in <module>
[WARNING] stderr:     IlislifeApp().run()
[WARNING] stderr:   File "/Users/m-takeuchi/.pyenv/versions/3.4.3/lib/python3.4/site-packages/kivy/app.py", line 828, in run
[WARNING] stderr:     runTouchApp()
[WARNING] stderr:   File "/Users/m-takeuchi/.pyenv/versions/3.4.3/lib/python3.4/site-packages/kivy/base.py", line 487, in runTouchApp
[WARNING] stderr:     EventLoop.window.mainloop()
[WARNING] stderr:   File "/Users/m-takeuchi/.pyenv/versions/3.4.3/lib/python3.4/site-packages/kivy/core/window/window_sdl2.py", line 637, in mainloop
[WARNING] stderr:     self._mainloop()
[WARNING] stderr:   File "/Users/m-takeuchi/.pyenv/versions/3.4.3/lib/python3.4/site-packages/kivy/core/window/window_sdl2.py", line 390, in _mainloop
[WARNING] stderr:     EventLoop.idle()
[WARNING] stderr:   File "/Users/m-takeuchi/.pyenv/versions/3.4.3/lib/python3.4/site-packages/kivy/base.py", line 330, in idle
[WARNING] stderr:     self.dispatch_input()
[WARNING] stderr:   File "/Users/m-takeuchi/.pyenv/versions/3.4.3/lib/python3.4/site-packages/kivy/base.py", line 315, in dispatch_input
[WARNING] stderr:     post_dispatch_input(*pop(0))
[WARNING] stderr:   File "/Users/m-takeuchi/.pyenv/versions/3.4.3/lib/python3.4/site-packages/kivy/base.py", line 221, in post_dispatch_input
[WARNING] stderr:     listener.dispatch('on_motion', etype, me)
[WARNING] stderr:   File "kivy/_event.pyx", line 718, in kivy._event.EventDispatcher.dispatch (/var/folders/hj/v3sdjs454rb_9gwwlp9j3p4c0000gn/T/pip-keicfvdj-build/kivy/_event.c:7726)
[WARNING] stderr:   File "/Users/m-takeuchi/.pyenv/versions/3.4.3/lib/python3.4/site-packages/kivy/core/window/__init__.py", line 1074, in on_motion
[WARNING] stderr:     self.dispatch('on_touch_down', me)
[WARNING] stderr:   File "kivy/_event.pyx", line 718, in kivy._event.EventDispatcher.dispatch (/var/folders/hj/v3sdjs454rb_9gwwlp9j3p4c0000gn/T/pip-keicfvdj-build/kivy/_event.c:7726)
[WARNING] stderr:   File "/Users/m-takeuchi/.pyenv/versions/3.4.3/lib/python3.4/site-packages/kivy/core/window/__init__.py", line 1090, in on_touch_down
[WARNING] stderr:     if w.dispatch('on_touch_down', touch):
[WARNING] stderr:   File "kivy/_event.pyx", line 718, in kivy._event.EventDispatcher.dispatch (/var/folders/hj/v3sdjs454rb_9gwwlp9j3p4c0000gn/T/pip-keicfvdj-build/kivy/_event.c:7726)
[WARNING] stderr:   File "/Users/m-takeuchi/.pyenv/versions/3.4.3/lib/python3.4/site-packages/kivy/uix/widget.py", line 457, in on_touch_down
[WARNING] stderr:     if child.dispatch('on_touch_down', touch):
[WARNING] stderr:   File "kivy/_event.pyx", line 718, in kivy._event.EventDispatcher.dispatch (/var/folders/hj/v3sdjs454rb_9gwwlp9j3p4c0000gn/T/pip-keicfvdj-build/kivy/_event.c:7726)
[WARNING] stderr:   File "/Users/m-takeuchi/.pyenv/versions/3.4.3/lib/python3.4/site-packages/kivy/uix/widget.py", line 457, in on_touch_down
[WARNING] stderr:     if child.dispatch('on_touch_down', touch):
[WARNING] stderr:   File "kivy/_event.pyx", line 718, in kivy._event.EventDispatcher.dispatch (/var/folders/hj/v3sdjs454rb_9gwwlp9j3p4c0000gn/T/pip-keicfvdj-build/kivy/_event.c:7726)
[WARNING] stderr:   File "/Users/m-takeuchi/.pyenv/versions/3.4.3/lib/python3.4/site-packages/kivy/uix/widget.py", line 457, in on_touch_down
[WARNING] stderr:     if child.dispatch('on_touch_down', touch):
[WARNING] stderr:   File "kivy/_event.pyx", line 718, in kivy._event.EventDispatcher.dispatch (/var/folders/hj/v3sdjs454rb_9gwwlp9j3p4c0000gn/T/pip-keicfvdj-build/kivy/_event.c:7726)
[WARNING] stderr:   File "/Users/m-takeuchi/.pyenv/versions/3.4.3/lib/python3.4/site-packages/kivy/uix/behaviors/button.py", line 151, in on_touch_down
[WARNING] stderr:     self.dispatch('on_press')
[WARNING] stderr:   File "kivy/_event.pyx", line 714, in kivy._event.EventDispatcher.dispatch (/var/folders/hj/v3sdjs454rb_9gwwlp9j3p4c0000gn/T/pip-keicfvdj-build/kivy/_event.c:7681)
[WARNING] stderr:   File "kivy/_event.pyx", line 1224, in kivy._event.EventObservers.dispatch (/var/folders/hj/v3sdjs454rb_9gwwlp9j3p4c0000gn/T/pip-keicfvdj-build/kivy/_event.c:13524)
[WARNING] stderr:   File "kivy/_event.pyx", line 1108, in kivy._event.EventObservers._dispatch (/var/folders/hj/v3sdjs454rb_9gwwlp9j3p4c0000gn/T/pip-keicfvdj-build/kivy/_event.c:12356)
[WARNING] stderr:   File "/Users/m-takeuchi/.pyenv/versions/3.4.3/lib/python3.4/site-packages/kivy/lang/builder.py", line 64, in custom_callback
[WARNING] stderr:     exec(__kvlang__.co_value, idmap)
[WARNING] stderr:   File "./ilislife.kv", line 76, in <module>
[WARNING] stderr:     on_press: root.on_command('connect/disconnect')
[WARNING] stderr:   File "main.py", line 103, in on_command
[WARNING] stderr:     Ve_obj, Ic_obj, Ig_obj = self.connect_device()
[WARNING] stderr:   File "main.py", line 166, in connect_device
[WARNING] stderr:     Ve_obj = BPHV.E3640A(tty, VeAddr)
[WARNING] stderr:   File "/Users/m-takeuchi/research/kyoto-u/exp_data/ILIS/ILIS_program_t-i/ilislife/e3640a_prologix.py", line 15, in __init__
[WARNING] stderr:     GPIBUSB.__init__(self, portNum, reset=False)
[WARNING] stderr:   File "/Users/m-takeuchi/research/kyoto-u/exp_data/ILIS/ILIS_program_t-i/ilislife/prologix.py", line 48, in __init__
[WARNING] stderr:     self.raw = serial.Serial(self._serPort_,9600,timeout=1,rtscts=True) #open the serial on COM n+1
[WARNING] stderr:   File "/Users/m-takeuchi/.pyenv/versions/3.4.3/lib/python3.4/site-packages/serial/serialutil.py", line 182, in __init__
[WARNING] stderr:     self.open()
[WARNING] stderr:   File "/Users/m-takeuchi/.pyenv/versions/3.4.3/lib/python3.4/site-packages/serial/serialposix.py", line 247, in open
[WARNING] stderr:     raise SerialException(msg.errno, "could not open port {}: {}".format(self._port, msg))
[WARNING] stderr: serial.serialutil.SerialException: [Errno 2] could not open port /dev/tty.usbserial-PXWV0AMC: [Errno 2] No such file or directory: '/dev/tty.usbserial-PXWV0AMC'
